Failure # 1 (occurred at 2020-12-22_00-24-17)
Traceback (most recent call last):
  File "C:\Users\nhian\AppData\Roaming\Python\Python37\site-packages\ray\tune\trial_runner.py", line 726, in _process_trial
    result = self.trial_executor.fetch_result(trial)
  File "C:\Users\nhian\AppData\Roaming\Python\Python37\site-packages\ray\tune\ray_trial_executor.py", line 489, in fetch_result
    result = ray.get(trial_future[0], timeout=DEFAULT_GET_TIMEOUT)
  File "C:\Users\nhian\AppData\Roaming\Python\Python37\site-packages\ray\worker.py", line 1452, in get
    raise value.as_instanceof_cause()
ray.exceptions.RayTaskError(TuneError): [36mray::ImplicitFunc.train()[39m (pid=51096, ip=192.168.1.102)
  File "python\ray\_raylet.pyx", line 482, in ray._raylet.execute_task
  File "python\ray\_raylet.pyx", line 436, in ray._raylet.execute_task.function_executor
  File "C:\Users\nhian\AppData\Roaming\Python\Python37\site-packages\ray\function_manager.py", line 553, in actor_method_executor
    return method(actor, *args, **kwargs)
  File "C:\Users\nhian\AppData\Roaming\Python\Python37\site-packages\ray\tune\trainable.py", line 336, in train
    result = self.step()
  File "C:\Users\nhian\AppData\Roaming\Python\Python37\site-packages\ray\tune\function_runner.py", line 366, in step
    self._report_thread_runner_error(block=True)
  File "C:\Users\nhian\AppData\Roaming\Python\Python37\site-packages\ray\tune\function_runner.py", line 513, in _report_thread_runner_error
    .format(err_tb_str)))
ray.tune.error.TuneError: Trial raised an exception. Traceback:
[36mray::ImplicitFunc.train()[39m (pid=51096, ip=192.168.1.102)
  File "C:\Users\nhian\AppData\Roaming\Python\Python37\site-packages\ray\tune\function_runner.py", line 248, in run
    self._entrypoint()
  File "C:\Users\nhian\AppData\Roaming\Python\Python37\site-packages\ray\tune\function_runner.py", line 316, in entrypoint
    self._status_reporter.get_checkpoint())
  File "C:\Users\nhian\AppData\Roaming\Python\Python37\site-packages\ray\tune\function_runner.py", line 575, in _trainable_func
    output = fn()
  File "<ipython-input-60-14097d1ead74>", line 118, in trainNN
  File "C:\ProgramData\Anaconda3\lib\site-packages\torch\serialization.py", line 361, in save
    with _open_file_like(f, 'wb') as opened_file:
  File "C:\ProgramData\Anaconda3\lib\site-packages\torch\serialization.py", line 229, in _open_file_like
    return _open_file(name_or_buffer, mode)
  File "C:\ProgramData\Anaconda3\lib\site-packages\torch\serialization.py", line 210, in __init__
    super(_open_file, self).__init__(open(name, mode))
FileNotFoundError: [Errno 2] No such file or directory: 'C:\\Users\\nhian\\Dropbox\\My PC (DESKTOP-L6D69LH)\\Documents\\GitHub\\LMM_SABR\\tune_checkpoint\\trials\\nn_step_18\\nn11b3a73a\\checkpoint_0\\checkpoint\\chk.pkl'

